<?xml version="1.0"?>

<robot xmlns:xacro="http://playerstage.sourceforge.net/gazebo/xmlschema/#interface" name="solo">

  <!-- See https://github.com/open-dynamic-robot-initiative/open_robot_actuator_hardware/blob/master/mechanics/quadruped_robot_12dof_v1/README.md#quadruped-robot-12dof-v1 -->
  <!-- These are absoulte distance value, the sign are decided below -->
  <xacro:property name="base_2_HAA_x" value="${214.10 * 0.001}" />
  <xacro:property name="base_2_HAA_y" value="${87.50 * 0.001}" />

  <xacro:property name="HAA_2_HFE_y" value="${14.0 * 0.001}" />
  <xacro:property name="HAA_2_HFE_x" value="${19.5 * 0.001}" />

  <xacro:property name="base_2_HFE_x" value="${194.60 * 0.001}" />
  <xacro:property name="base_2_HFE_y" value="${101.50 * 0.001}" />

  <xacro:property name="HFE_2_KFE_y" value="${37.45 * 0.001}" />
  <xacro:property name="HFE_2_KFE_z" value="${160.00 * 0.001}" />

  <xacro:property name="KFE_2_FOOT_y" value="${9.0 * 0.001}" />
  <xacro:property name="KFE_2_FOOT_z" value="${160.00 * 0.001}" />

  <!-- Macro defining solo leg. -->
  <xacro:macro name="leg" params="prefix is_front is_right has_side_motion
                                  mesh_ext color_name color opacity">

    <xacro:if value="${has_side_motion}">
      <joint name="${prefix}_HAA" type="revolute">
        <parent link="base_link"/>
        <child link="${prefix}_SHOULDER"/>
        <limit effort="1000" lower="-10" upper="10" velocity="1000"/>
        <!-- joints rotates around the x-axis -->
        <axis xyz="1 0 0"/>
        <!-- placement of the joint -->
        <xacro:if value="${is_front}">
          <xacro:unless value="${is_right}">
            <origin xyz="${base_2_HAA_x} ${base_2_HAA_y} 0" rpy="0 0 0" />
          </xacro:unless>
          <xacro:if value="${is_right}">
            <origin xyz="${base_2_HAA_x} ${-base_2_HAA_y} 0" rpy="0 0 0" />
          </xacro:if>
        </xacro:if>
        <xacro:unless value="${is_front}">
          <xacro:unless value="${is_right}">
            <origin xyz="${-base_2_HAA_x} ${base_2_HAA_y} 0" rpy="0 0 0" />
          </xacro:unless>
          <xacro:if value="${is_right}">
            <origin xyz="${-base_2_HAA_x} ${-base_2_HAA_y} 0" rpy="0 0 0" />
          </xacro:if>
        </xacro:unless>
        <!-- pybullet simulation parameters -->
        <dynamics damping="0.0" friction="0.0"/>
      </joint>
      <link name="${prefix}_SHOULDER">
        <!-- HAA VISUAL -->
        <visual>
            <xacro:unless value="${is_right}">
                <xacro:if value="${is_front}">
                    <origin xyz="0.01950 0 0" rpy="0 0 0" />
                    <geometry>
                        <mesh filename="package://robot_properties_solo/resources/meshes/${mesh_ext}/solo12/solo12_hip_fe_fl.${mesh_ext}"/>
                    </geometry>
                </xacro:if>
                <xacro:unless value="${is_front}">
                    <origin xyz="-0.01950 0 0" rpy="0 0 0" />
                    <geometry>
                        <mesh filename="package://robot_properties_solo/resources/meshes/${mesh_ext}/solo12/solo12_hip_fe_hl.${mesh_ext}"/>
                    </geometry>
                </xacro:unless>
            </xacro:unless>
            <xacro:if value="${is_right}">
                <xacro:if value="${is_front}">
                    <origin xyz="0.01950 0 0" rpy="0 0 0" />
                    <geometry>
                        <mesh filename="package://robot_properties_solo/resources/meshes/${mesh_ext}/solo12/solo12_hip_fe_fr.${mesh_ext}"/>
                    </geometry>
                </xacro:if>
                <xacro:unless value="${is_front}">
                    <origin xyz="-0.01950 0 0" rpy="0 0 0" />
                    <geometry>
                        <mesh filename="package://robot_properties_solo/resources/meshes/${mesh_ext}/solo12/solo12_hip_fe_hr.${mesh_ext}"/>
                    </geometry>
                </xacro:unless>
            </xacro:if>
            <material name="${color_name}">
                <color rgba="${color} ${opacity}"/>
            </material>
        </visual>
        <!-- HAA LINK COLLISION -->
        <collision>
                <xacro:unless value="${is_right}">
                <xacro:if value="${is_front}">
                    <origin xyz="0.01950 0 0" rpy="0 0 0" />
                    <geometry>
                        <mesh filename="package://robot_properties_solo/resources/meshes/${mesh_ext}/solo12/solo12_hip_fe_fl.${mesh_ext}"/>
                    </geometry>
                </xacro:if>
                <xacro:unless value="${is_front}">
                    <origin xyz="-0.01950 0 0" rpy="0 0 0" />
                    <geometry>
                        <mesh filename="package://robot_properties_solo/resources/meshes/${mesh_ext}/solo12/solo12_hip_fe_hl.${mesh_ext}"/>
                    </geometry>
                </xacro:unless>
            </xacro:unless>
            <xacro:if value="${is_right}">
                <xacro:if value="${is_front}">
                    <origin xyz="0.01950 0 0" rpy="0 0 0" />
                    <geometry>
                        <mesh filename="package://robot_properties_solo/resources/meshes/${mesh_ext}/solo12/solo12_hip_fe_fr.${mesh_ext}"/>
                    </geometry>
                </xacro:if>
                <xacro:unless value="${is_front}">
                    <origin xyz="-0.01950 0 0" rpy="0 0 0" />
                    <geometry>
                        <mesh filename="package://robot_properties_solo/resources/meshes/${mesh_ext}/solo12/solo12_hip_fe_hr.${mesh_ext}"/>
                    </geometry>
                </xacro:unless>
            </xacro:if>
            <material name="${color_name}">
                <color rgba="${color} ${opacity}"/>
            </material>
        </collision>
        <inertial>
          <mass value="0.14196048"/>
          <xacro:if value="${is_front}">
            <xacro:unless value="${is_right}">
              <!-- HAA body inertia -->
              <origin xyz="-0.09407251 -0.00438935 0.00001384" rpy="0 0 0" />
              <inertia ixx="0.00002802" ixy="0.00003687" ixz="-0.00000009"
                                        iyy="0.00038264" iyz="0.00000000"
                                                         izz="0.00038050"/>
            </xacro:unless>
            <xacro:if value="${is_right}">
              <!-- HAA body inertia -->
              <origin xyz="-0.09407251 0.00438935 -0.00001384" rpy="0 0 0" />
              <inertia ixx="0.00002802" ixy="-0.00003687" ixz="0.00000009"
                                        iyy="0.00038264"  iyz="0.00000000"
                                                          izz="0.00038050"/>
            </xacro:if>
          </xacro:if>
          <xacro:unless value="${is_front}">
            <xacro:unless value="${is_right}">
              <!-- HAA body inertia -->
              <origin xyz="0.09407251 -0.00438935 -0.00001384" rpy="0 0 0" />
              <inertia ixx="0.00002802" ixy="-0.00003687" ixz="-0.00000009"
                                        iyy="0.00038264"  iyz="0.00000000"
                                                          izz="0.00038050"/>
            </xacro:unless>
            <xacro:if value="${is_right}">
              <!-- HAA body inertia -->
              <origin xyz="0.09407251 0.00438935 0.00001384" rpy="0 0 0" />
              <inertia ixx="0.00002802" ixy="0.00003687" ixz="0.00000009"
                                        iyy="0.00038264" iyz="0.00000000"
                                                         izz="0.00038050"/>
            </xacro:if>
          </xacro:unless>
        </inertial>
      </link>
      <joint name="${prefix}_HFE" type="revolute">
        <parent link="${prefix}_SHOULDER"/>
        <child link="${prefix}_UPPER_LEG"/>
        <limit effort="1000" lower="-10" upper="10" velocity="1000"/>
        <!-- joints rotates around the y-axis -->
        <axis xyz="0 1 0"/>
        <!-- placement of the joint -->
        <xacro:if value="${is_front}">
          <xacro:unless value="${is_right}">
            <origin xyz="${-HAA_2_HFE_x} ${HAA_2_HFE_y} 0" rpy="0 0 0" />
          </xacro:unless>
          <xacro:if value="${is_right}">
            <origin xyz="${-HAA_2_HFE_x} ${-HAA_2_HFE_y} 0" rpy="0 0 0" />
          </xacro:if>
        </xacro:if>
        <xacro:unless value="${is_front}">
          <xacro:unless value="${is_right}">
            <origin xyz="${HAA_2_HFE_x} ${HAA_2_HFE_y} 0" rpy="0 0 0" />
          </xacro:unless>
          <xacro:if value="${is_right}">
            <origin xyz="${HAA_2_HFE_x} ${-HAA_2_HFE_y} 0" rpy="0 0 0" />
          </xacro:if>
        </xacro:unless>
        <!-- pybullet simulation parameters -->
        <dynamics damping="0.0" friction="0.0"/>
      </joint>
    </xacro:if>
    <xacro:unless value="${has_side_motion}">
      <!-- Joint between the base and the ${prefix} upper leg -->
      <joint name="${prefix}_HFE" type="revolute">
        <parent link="base_link"/>
        <child link="${prefix}_UPPER_LEG"/>
        <limit effort="1000" lower="-10" upper="10" velocity="1000"/>
        <!-- joints rotates around the y-axis -->
        <axis xyz="0 1 0"/>
        <!-- placement of the joint -->
        <xacro:if value="${is_front}">
          <xacro:unless value="${is_right}">
            <origin xyz="${base_2_HFE_x} ${base_2_HFE_y} 0" rpy="0 0 0" />
          </xacro:unless>
          <xacro:if value="${is_right}">
            <origin xyz="${base_2_HFE_x} ${-base_2_HFE_y} 0" rpy="0 0 0" />
          </xacro:if>
        </xacro:if>
        <xacro:unless value="${is_front}">
          <xacro:unless value="${is_right}">
            <origin xyz="${-base_2_HFE_x} ${base_2_HFE_y} 0" rpy="0 0 0" />
          </xacro:unless>
          <xacro:if value="${is_right}">
            <origin xyz="${-base_2_HFE_x} ${-base_2_HFE_y} 0" rpy="0 0 0" />
          </xacro:if>
        </xacro:unless>
        <!-- pybullet simulation parameters -->
        <dynamics damping="0.0" friction="0.0"/>
      </joint>
    </xacro:unless>

    <link name="${prefix}_UPPER_LEG">
      <!-- UPPER LEG LINK INERTIAL -->
      <xacro:unless value="${is_right}">
        <!-- Left upper leg inertia -->
        <inertial>
        <mass value="0.14737324"/>
        <origin xyz="0.00001530 0.01767640 -0.07838230" rpy="0 0 0" />
        <inertia ixx="0.00041540"  ixy="0.00000000" ixz="0.00000010"
                                   iyy="0.00041637" iyz="-0.00004589"
                                                    izz="0.00002982"/>
        </inertial>
      </xacro:unless>
      <xacro:if value="${is_right}">
        <!-- Right upper leg inertia -->
        <inertial>
        <mass value="0.14737324"/>
        <origin xyz="-0.00001530 -0.01767640 -0.07838230" rpy="0 0 0" />
        <inertia ixx="0.00041540"  ixy="0.00000000" ixz="-0.00000010"
                                   iyy="0.00041637" iyz="0.00004589"
                                                    izz="0.00002982"/>
        </inertial>
      </xacro:if>
      <!-- UPPER LEG LINK VISUAL -->
      <visual>
        <origin xyz="0 0 0" rpy="0 0 0" />
        <geometry>
          <xacro:unless value="${is_right}">
            <mesh filename="package://robot_properties_solo/resources/meshes/${mesh_ext}/without_foot/solo_upper_leg_left_side.${mesh_ext}"/>
          </xacro:unless>
          <xacro:if value="${is_right}">
            <mesh filename="package://robot_properties_solo/resources/meshes/${mesh_ext}/without_foot/solo_upper_leg_right_side.${mesh_ext}"/>
          </xacro:if>
        </geometry>
        <material name="${color_name}">
            <color rgba="${color} ${opacity}"/>
        </material>
      </visual>
      <!-- UPPER LEG LINK COLLISION -->
      <collision>
        <origin xyz="0 0 0" rpy="0 0 0" />
        <geometry>
          <xacro:unless value="${is_right}">
            <mesh filename="package://robot_properties_solo/resources/meshes/${mesh_ext}/without_foot/solo_upper_leg_left_side.${mesh_ext}"/>
          </xacro:unless>
          <xacro:if value="${is_right}">
            <mesh filename="package://robot_properties_solo/resources/meshes/${mesh_ext}/without_foot/solo_upper_leg_right_side.${mesh_ext}"/>
          </xacro:if>
        </geometry>
        <material name="${color_name}">
            <color rgba="${color} ${opacity}"/>
        </material>
      </collision>
      <!-- Bullet specific paramters -->
      <contact>
        <lateral_friction value="1.0"/>
        <restitution value="0.5"/>
      </contact>
    </link> <!-- END UPPER LEG LINK -->

    <!-- KFE: Joint between the upper leg and the lower leg -->
    <joint name="${prefix}_KFE" type="revolute">
      <parent link="${prefix}_UPPER_LEG"/>
      <child link="${prefix}_LOWER_LEG"/>
      <limit effort="1000" lower="-10" upper="10" velocity="1000"/>
      <!-- joints rotates around the y-axis -->
      <axis xyz="0 1 0"/>
      <!-- placement of the joint -->
      <xacro:if value="${is_front}">
        <xacro:unless value="${is_right}">
          <origin xyz="0 ${HFE_2_KFE_y} ${-HFE_2_KFE_z}" rpy="0 0 0" />
        </xacro:unless>
        <xacro:if value="${is_right}">
          <origin xyz="0 ${-HFE_2_KFE_y} ${-HFE_2_KFE_z}" rpy="0 0 0" />
        </xacro:if>
      </xacro:if>
      <xacro:unless value="${is_front}">
        <xacro:unless value="${is_right}">
          <origin xyz="0 ${HFE_2_KFE_y} ${-HFE_2_KFE_z}" rpy="0 0 0" />
        </xacro:unless>
        <xacro:if value="${is_right}">
          <origin xyz="0 ${-HFE_2_KFE_y} ${-HFE_2_KFE_z}" rpy="0 0 0" />
        </xacro:if>
      </xacro:unless>
      <!-- pybullet simulation parameters -->
      <dynamics damping="0.0" friction="0.0"/>
    </joint>

    <link name="${prefix}_LOWER_LEG">
      <!-- LOWER LEG LINK INERTIAL -->
      <xacro:unless value="${is_right}">
        <!-- Left lower leg inertia -->
        <inertial>
        <mass value="0.02318294"/>
        <origin xyz="0.00000000 0.00776716 -0.07003876" rpy="0 0 0" />
        <inertia ixx="0.00008508" ixy="0.00000000"  ixz="0.00000000"
                                  iyy="0.00008580"  iyz="-0.00000200"
                                                    izz="0.00000139"/>
        </inertial>
      </xacro:unless>
      <xacro:if value="${is_right}">
        <!-- Right lower leg inertia -->
        <inertial>
        <mass value="0.02318294"/>
        <origin xyz="0.00000000 -0.00776716 -0.07003876" rpy="0 0 0" />
        <inertia ixx="0.00008508" ixy="0.00000000"  ixz="0.00000000"
                                  iyy="0.00008580"  iyz="0.00000200"
                                                    izz="0.00000139"/>
        </inertial>
      </xacro:if>
      <!-- LOWER LEG LINK VISUAL -->
      <visual>
        <origin xyz="0 0 0" rpy="0 0 0" />
        <geometry>
          <xacro:unless value="${is_right}">
            <mesh filename="package://robot_properties_solo/resources/meshes/${mesh_ext}/without_foot/solo_lower_leg_v2_left_side.${mesh_ext}"/>
          </xacro:unless>
          <xacro:if value="${is_right}">
            <mesh filename="package://robot_properties_solo/resources/meshes/${mesh_ext}/without_foot/solo_lower_leg_v2_right_side.${mesh_ext}"/>
          </xacro:if>
        </geometry>
        <material name="${color_name}">
            <color rgba="${color} ${opacity}"/>
        </material>
      </visual>
      <!-- LOWER LEG LINK COLLISION -->
      <collision>
        <origin xyz="0 0 0" rpy="0 0 0" />
        <geometry>
          <xacro:unless value="${is_right}">
            <mesh filename="package://robot_properties_solo/resources/meshes/${mesh_ext}/without_foot/solo_lower_leg_v2_left_side.${mesh_ext}"/>
          </xacro:unless>
          <xacro:if value="${is_right}">
            <mesh filename="package://robot_properties_solo/resources/meshes/${mesh_ext}/without_foot/solo_lower_leg_v2_right_side.${mesh_ext}"/>
          </xacro:if>
        </geometry>
        <material name="${color_name}">
            <color rgba="${color} ${opacity}"/>
        </material>
      </collision>
      <!-- Bullet specific paramters -->
      <contact>
        <lateral_friction value="1.0"/>
        <restitution value="0.5"/>
      </contact>
    </link> <!-- END LOWER LEG LINK -->

    <!-- Joint between the lower leg and the ankle,
         this is only a dummy joint such that we
         can assign coordinate frames to foot-->
    <joint name="${prefix}_ANKLE" type="fixed">
      <parent link="${prefix}_LOWER_LEG"/>
      <child link="${prefix}_FOOT"/>
      <!-- Joint placement -->
      <xacro:unless value="${is_right}">
        <origin xyz="0 ${KFE_2_FOOT_y} ${-KFE_2_FOOT_z}" rpy="0 0 0" />
      </xacro:unless>
      <xacro:if value="${is_right}">
        <origin xyz="0 ${-KFE_2_FOOT_y} ${-KFE_2_FOOT_z}" rpy="0 0 0" />
      </xacro:if>
      <!-- Limits -->
      <limit effort="1000" lower="-10" upper="10" velocity="1000"/>
      <!-- pybullet simulation parameters -->
      <dynamics damping="0.0" friction="0.0"/>
    </joint>

    <link name="${prefix}_FOOT">
      <!-- FOOT INERTIAL -->
      <inertial>
        <origin xyz="0 0 0" rpy="0 0 0" />
        <mass value="0.0"/>
        <inertia ixx="0.0" ixy="0.0" ixz="0.0"
                           iyy="0.0" iyz="0.0"
                                     izz="0.0"/>
      </inertial>
    </link> <!-- END FOOT LINK -->

  </xacro:macro>
</robot>
